Traceback (most recent call last):
  File "/home/petri/venv/python3/lib/python3.9/site-packages/jupyter_cache/executors/utils.py", line 51, in single_nb_execution
    executenb(
  File "/home/petri/venv/python3/lib/python3.9/site-packages/nbclient/client.py", line 1117, in execute
    return NotebookClient(nb=nb, resources=resources, km=km, **kwargs).execute()
  File "/home/petri/venv/python3/lib/python3.9/site-packages/nbclient/util.py", line 78, in wrapped
    return just_run(coro(*args, **kwargs))
  File "/home/petri/venv/python3/lib/python3.9/site-packages/nbclient/util.py", line 57, in just_run
    return loop.run_until_complete(coro)
  File "/usr/lib/python3.9/asyncio/base_events.py", line 642, in run_until_complete
    return future.result()
  File "/home/petri/venv/python3/lib/python3.9/site-packages/nbclient/client.py", line 558, in async_execute
    await self.async_execute_cell(
  File "/home/petri/venv/python3/lib/python3.9/site-packages/nbclient/client.py", line 862, in async_execute_cell
    self._check_raise_for_error(cell, exec_reply)
  File "/home/petri/venv/python3/lib/python3.9/site-packages/nbclient/client.py", line 765, in _check_raise_for_error
    raise CellExecutionError.from_cell_and_msg(cell, exec_reply_content)
nbclient.exceptions.CellExecutionError: An error occurred while executing the following cell:
------------------
data=pd.read_hdf('data/heatneed.h5').dropna()
data.head()
------------------

[0;31m---------------------------------------------------------------------------[0m
[0;31mFileNotFoundError[0m                         Traceback (most recent call last)
[0;32m/tmp/ipykernel_854606/1323350634.py[0m in [0;36m<module>[0;34m[0m
[0;32m----> 1[0;31m [0mdata[0m[0;34m=[0m[0mpd[0m[0;34m.[0m[0mread_hdf[0m[0;34m([0m[0;34m'data/heatneed.h5'[0m[0;34m)[0m[0;34m.[0m[0mdropna[0m[0;34m([0m[0;34m)[0m[0;34m[0m[0;34m[0m[0m
[0m[1;32m      2[0m [0mdata[0m[0;34m.[0m[0mhead[0m[0;34m([0m[0;34m)[0m[0;34m[0m[0;34m[0m[0m

[0;32m~/venv/python3/lib/python3.9/site-packages/pandas/io/pytables.py[0m in [0;36mread_hdf[0;34m(path_or_buf, key, mode, errors, where, start, stop, columns, iterator, chunksize, **kwargs)[0m
[1;32m    425[0m [0;34m[0m[0m
[1;32m    426[0m         [0;32mif[0m [0;32mnot[0m [0mexists[0m[0;34m:[0m[0;34m[0m[0;34m[0m[0m
[0;32m--> 427[0;31m             [0;32mraise[0m [0mFileNotFoundError[0m[0;34m([0m[0;34mf"File {path_or_buf} does not exist"[0m[0;34m)[0m[0;34m[0m[0;34m[0m[0m
[0m[1;32m    428[0m [0;34m[0m[0m
[1;32m    429[0m         [0mstore[0m [0;34m=[0m [0mHDFStore[0m[0;34m([0m[0mpath_or_buf[0m[0;34m,[0m [0mmode[0m[0;34m=[0m[0mmode[0m[0;34m,[0m [0merrors[0m[0;34m=[0m[0merrors[0m[0;34m,[0m [0;34m**[0m[0mkwargs[0m[0;34m)[0m[0;34m[0m[0;34m[0m[0m

[0;31mFileNotFoundError[0m: File data/heatneed.h5 does not exist
FileNotFoundError: File data/heatneed.h5 does not exist

